import java.io.IOException;
import java.util.Random;

public class ExceptionTest13 {

	public static void myRandom() throws UserException {
		Random r = new Random();
		int num =r.nextInt(3); // 0 , 1, 2
		//가정? 0 이면 예외이다.
		System.out.println("myRandom r==="+ num);
		if(num== 0) {
			throw new UserException("랜덤값 0이 나와 예외발생");
			//throw new ArithmeticException("랜덤값 0이 나와 예외발생");
		}
	}
	
	public static void main(String[] args) {
		System.out.println("프로그램 시작");
		try {
			myRandom();
		} catch (UserException e) {
			// TODO Auto-generated catch block
			System.out.println(e.getMessage());
			e.printStackTrace();
		}
		System.out.println("프로그램 종료");
	}
}
